using System;
using System.Threading.Tasks;

namespace ExceptionHandling
{
    class ExceptionHandling
    {
        static void Main(string[] args)
        {
            try
            {
                TestException();
            }
            catch (AggregateException ae)
            {
                foreach (var e in ae.InnerExceptions)
                {
                    Console.WriteLine($"Handled elsewhere: {e.GetType()}");
                }
            }

            Console.WriteLine("Main program done.");
            Console.ReadKey();
        }

        private static void TestException()
        {
            var t1 = Task.Factory.StartNew(() =>
            {
                throw new InvalidOperationException("Can't do this!") { Source = "t1" };
            });

            var t2 = Task.Factory.StartNew(() =>
            {
                throw new AccessViolationException("Can't access this!") { Source = "t2" };
            });

            try
            {
                Task.WaitAll(t1, t2);
            }
            catch (AggregateException ae)
            {
                ae.Handle(e =>
                {
                    if (e is InvalidOperationException)
                    {
                        Console.WriteLine("Has been handle invlid operation");
                        return true;
                    }

                    return false;
                });
            }
        }

    }
}

